[2024-08-08 08:00:58,023] {taskinstance.py:877} INFO - Dependencies all met for <TaskInstance: dota_dag.extract_heroes 2024-08-08T08:00:56.986609+00:00 [queued]>
[2024-08-08 08:00:58,043] {taskinstance.py:877} INFO - Dependencies all met for <TaskInstance: dota_dag.extract_heroes 2024-08-08T08:00:56.986609+00:00 [queued]>
[2024-08-08 08:00:58,044] {taskinstance.py:1068} INFO - 
--------------------------------------------------------------------------------
[2024-08-08 08:00:58,045] {taskinstance.py:1069} INFO - Starting attempt 1 of 2
[2024-08-08 08:00:58,046] {taskinstance.py:1070} INFO - 
--------------------------------------------------------------------------------
[2024-08-08 08:00:58,067] {taskinstance.py:1089} INFO - Executing <Task(PythonOperator): extract_heroes> on 2024-08-08T08:00:56.986609+00:00
[2024-08-08 08:00:58,071] {standard_task_runner.py:52} INFO - Started process 53 to run task
[2024-08-08 08:00:58,075] {standard_task_runner.py:76} INFO - Running: ['airflow', 'tasks', 'run', 'dota_dag', 'extract_heroes', '2024-08-08T08:00:56.986609+00:00', '--job-id', '5', '--pool', 'default_pool', '--raw', '--subdir', 'DAGS_FOLDER/dota.py', '--cfg-path', '/tmp/tmp8fx74pf2', '--error-file', '/tmp/tmpscsljmgt']
[2024-08-08 08:00:58,076] {standard_task_runner.py:77} INFO - Job 5: Subtask extract_heroes
[2024-08-08 08:00:58,137] {logging_mixin.py:104} INFO - Running <TaskInstance: dota_dag.extract_heroes 2024-08-08T08:00:56.986609+00:00 [running]> on host ec67c4f7e31a
[2024-08-08 08:00:58,183] {taskinstance.py:1283} INFO - Exporting the following env vars:
AIRFLOW_CTX_DAG_OWNER=airflow
AIRFLOW_CTX_DAG_ID=dota_dag
AIRFLOW_CTX_TASK_ID=extract_heroes
AIRFLOW_CTX_EXECUTION_DATE=2024-08-08T08:00:56.986609+00:00
AIRFLOW_CTX_DAG_RUN_ID=manual__2024-08-08T08:00:56.986609+00:00
[2024-08-08 08:00:58,187] {taskinstance.py:1482} ERROR - Task failed with exception
Traceback (most recent call last):
  File "/home/airflow/.local/lib/python3.6/site-packages/airflow/models/taskinstance.py", line 1138, in _run_raw_task
    self._prepare_and_execute_task_with_callbacks(context, task)
  File "/home/airflow/.local/lib/python3.6/site-packages/airflow/models/taskinstance.py", line 1311, in _prepare_and_execute_task_with_callbacks
    result = self._execute_task(context, task_copy)
  File "/home/airflow/.local/lib/python3.6/site-packages/airflow/models/taskinstance.py", line 1341, in _execute_task
    result = task_copy.execute(context=context)
  File "/home/airflow/.local/lib/python3.6/site-packages/airflow/operators/python.py", line 117, in execute
    return_value = self.execute_callable()
  File "/home/airflow/.local/lib/python3.6/site-packages/airflow/operators/python.py", line 128, in execute_callable
    return self.python_callable(*self.op_args, **self.op_kwargs)
  File "/opt/airflow/dags/dota.py", line 24, in extract_heroes
    etl_dota.extract('all_heroes_id')
  File "/opt/airflow/dags/etl_dota.py", line 5, in extract
    df = pd.read_csv(f'data/rawest{filename}.csv')
  File "/home/airflow/.local/lib/python3.6/site-packages/pandas/io/parsers.py", line 688, in read_csv
    return _read(filepath_or_buffer, kwds)
  File "/home/airflow/.local/lib/python3.6/site-packages/pandas/io/parsers.py", line 454, in _read
    parser = TextFileReader(fp_or_buf, **kwds)
  File "/home/airflow/.local/lib/python3.6/site-packages/pandas/io/parsers.py", line 948, in __init__
    self._make_engine(self.engine)
  File "/home/airflow/.local/lib/python3.6/site-packages/pandas/io/parsers.py", line 1180, in _make_engine
    self._engine = CParserWrapper(self.f, **self.options)
  File "/home/airflow/.local/lib/python3.6/site-packages/pandas/io/parsers.py", line 2010, in __init__
    self._reader = parsers.TextReader(src, **kwds)
  File "pandas/_libs/parsers.pyx", line 382, in pandas._libs.parsers.TextReader.__cinit__
  File "pandas/_libs/parsers.pyx", line 674, in pandas._libs.parsers.TextReader._setup_parser_source
FileNotFoundError: [Errno 2] No such file or directory: 'data/rawestall_heroes_id.csv'
[2024-08-08 08:00:58,203] {taskinstance.py:1532} INFO - Marking task as UP_FOR_RETRY. dag_id=dota_dag, task_id=extract_heroes, execution_date=20240808T080056, start_date=20240808T080058, end_date=20240808T080058
[2024-08-08 08:00:58,247] {local_task_job.py:146} INFO - Task exited with return code 1
